<?xml version="1.0"?>
<robot xmlns:xacro="http://www.ros.org/wiki/xacro" name="snake_robot" >

    <xacro:include filename="inertial_macros.xacro"/>
    <xacro:include filename="materials.xacro"/> 
   <!-- <xacro:include filename="gazebo_control.xacro"/> -->
   
   
   <xacro:include filename="ros2_control.xacro" />
    <!-- Constants for robot dimensions -->
    <xacro:property name="PI" value="3.1415926535897931"/>
    
     <odometry_frame>odom</odometry_frame>
    <robot_base_frame>head_link</robot_base_frame>

    <publish_odom>true</publish_odom>
    <publish_odom_tf>true</publish_odom_tf>
    <publish_joint_tf></publish_joint_tf>

    <!-- * * * * * * my file working fine * * * * * * * -->


     <!-- TAIL LINK WHICH I HAVE CALLED FOR HEAD LINK -->
    <link name="head_link">
        <visual>
            <geometry>
                      <box size="0.04 0.07 0.04"/>
            </geometry>            
            <material name="green"/>
            <origin xyz="0.0 0.035 0.02" rpy="0.0 0.0 0.0"/>
        </visual>
        <collision>
             <origin xyz="0.0 0.035 0.02"/>
            <geometry>
                    <box size="0.04 0.07 0.04"/>
            </geometry>
        </collision>
        <xacro:inertial_box mass="1" x="0.04" y="0.07" z="0.04">
              <origin xyz="0.0 0.035 0.02" rpy="0.0 0.0 0.0"/>
        </xacro:inertial_box>
      </link>

    <!-- JOINT BETWEEN THE TAIL AND THE FIRST LINK -->

    <joint name="link_head_1_joint" type="revolute">
        <parent link="head_link"/>
        <child link="link_1"/>
        <limit lower="-0.7854" upper="0.7854" velocity="50.0" effort="1000.0"/>
        <origin xyz="0.0 0.095 0.0" />
        <axis xyz="0 0 1"/>
        <joint_properties damping="6.0" friction="6.0"/>
      </joint>
    
    <!-- LINK 1 -->

    <link name="link_1">
        <visual>
            <geometry>
                    <box size="0.04 0.07 0.04"/>
            </geometry>
            <origin xyz="0.0 0.035 0.02" rpy="0.0 0.0 0.0"/>
          <material name="black"/>
        </visual>
        <collision>
            <origin xyz="0.0 0.035 0.02"/>
            <geometry>
                    <box size="0.04 0.07 0.04"/>
            </geometry>
        </collision>
        <xacro:inertial_box mass="1" x="0.04" y="0.07" z="0.04">
              <origin xyz="0.0 0.035 0.02" rpy="0.0 0.0 0.0"/>
        </xacro:inertial_box>
      </link>


    
    <!-- JOINT BETWEEM LINK 1 AND 2 -->

    <joint name="link_1_2_joint" type="revolute">
        <parent link="link_1"/>
        <child link="link_2"/>
        <limit lower="-0.7854" upper="0.7854" velocity="50.0" effort="1000.0"/>
        <origin xyz="0.0 0.095 0.0" />
        <axis xyz="0 0 1"/>
        <joint_properties damping="6.0" friction="6.0"/>
      </joint>
    
    <!-- LINK 2 -->

    <link name="link_2">
        <visual>
            <material name="orange"/>
            <origin xyz="0.0 0.035 0.02" rpy="0.0 0.0 0.0"/>           
            <geometry>
                <box size="0.04 0.07 0.04"/>
            </geometry>
        </visual>
        <collision>
            <origin xyz="0.0 0.035 0.02" rpy="0.0 0.0 0.0"/>
            <geometry>
                <box size="0.04 0.07 0.04"/>
            </geometry>
        </collision>
        <xacro:inertial_box mass="0.1" x="0.3" y="0.1" z="0.1">
            <origin xyz="0.0 0.035 0.02" rpy="0.0 0.0 0.0"/>
        </xacro:inertial_box>
    </link>   
       


    <!--JOINT BETWEEN LINK 2 AND LINK 3 -->

    <joint name="link_2_3_joint" type="revolute">
        <parent link="link_2"/>
        <child link="link_3"/>
        <limit lower="-0.7854" upper="0.7854" velocity="50.0" effort="1000.0"/>
        <origin xyz="0.0 0.095 0.0" />
        <axis xyz="0 0 1"/>
        <joint_properties damping="6.0" friction="6.0"/>
      </joint>
    
    <!-- LINK 3 -->

    <link name="link_3">
            <visual>
                <geometry>
                        <box size="0.04 0.07 0.04"/>
                </geometry>
                <origin xyz="0.0 0.035 0.02" rpy="0.0 0.0 0.0"/>
              <material name="black"/>
            </visual>
            <collision>
                <origin xyz="0.0 0.035 0.02"/>
                <geometry>
                        <box size="0.04 0.07 0.04"/>
                </geometry>
            </collision>
            <xacro:inertial_box mass="1" x="0.04" y="0.07" z="0.04">
                  <origin xyz="0.0 0.035 0.02" rpy="0.0 0.0 0.0"/>
            </xacro:inertial_box>
    </link>
       

    <!-- JOINT BETWEEN LINK 3 AND LINK 4 ***NOTE THAT LINK 4 IS THE HEAD -->

    <joint name="link_3_4_joint" type="revolute">
        <parent link="link_3"/>
        <child link="link_4"/>
        <limit lower="-0.7854" upper="0.7854" velocity="50.0" effort="1000.0"/>
        <origin xyz="0.0 0.095 0.0" />
        <axis xyz="0 0 1"/>
        <joint_properties damping="6.0" friction="6.0"/>
      </joint>
    
    <!-- LINK 4-->

    <link name="link_4">
        <visual>
            <geometry>
                    <box size="0.04 0.07 0.04"/>
            </geometry>
            <origin xyz="0.0 0.035 0.02" rpy="0.0 0.0 0.0"/>
          <material name="orange"/>
        </visual>
        <collision>
            <origin xyz="0.0 0.035 0.02"/>
            <geometry>
                    <box size="0.04 0.07 0.04"/>
            </geometry>
        </collision>
        <xacro:inertial_box mass="1" x="0.04" y="0.07" z="0.04">
              <origin xyz="0.0 0.035 0.02" rpy="0.0 0.0 0.0"/>
        </xacro:inertial_box>
    </link>


    <!-- JOINT BETWEEN LINK 4 AND LINK 5 ***NOTE THAT LINK 4 IS THE HEAD -->

    <joint name="link_4_5_joint" type="revolute">
        <parent link="link_4"/>
        <child link="link_5"/>
        <limit lower="-0.7854" upper="0.7854" velocity="50.0" effort="1000.0"/>
        <origin xyz="0.0 0.095 0.0" />
        <axis xyz="0 0 1"/>
        <joint_properties damping="6.0" friction="6.0"/>
      </joint>
    
    <!--  LINK 5-->

    <link name="link_5">
        <visual>
            <geometry>
                    <box size="0.04 0.07 0.04"/>
            </geometry>
            <origin xyz="0.0 0.035 0.02" rpy="0.0 0.0 0.0"/>
          <material name="black"/>
        </visual>
        <collision>
            <origin xyz="0.0 0.035 0.02"/>
            <geometry>
                    <box size="0.04 0.07 0.04"/>
            </geometry>
        </collision>
        <xacro:inertial_box mass="1" x="0.04" y="0.07" z="0.04">
              <origin xyz="0.0 0.035 0.02" rpy="0.0 0.0 0.0"/>
        </xacro:inertial_box>
    </link>

    <!-- JOINT BETWEEN LINK 5 AND LINK 6 ***NOTE THAT LINK 4 IS THE HEAD -->

    <joint name="link_5_6_joint" type="revolute">
        <parent link="link_5"/>
        <child link="link_6"/>
        <limit lower="-0.7854" upper="0.7854" velocity="50.0" effort="1000.0"/>
        <origin xyz="0.0 0.095 0.0" />
        <axis xyz="0 0 1"/>
        <joint_properties damping="6.0" friction="6.0"/>
      </joint>
    
    <!--  LINK 6-->

    <link name="link_6">
        <visual>
            <geometry>
                    <box size="0.04 0.07 0.04"/>
            </geometry>
            <origin xyz="0.0 0.035 0.02" rpy="0.0 0.0 0.0"/>
          <material name="orange"/>
        </visual>
        <collision>
            <origin xyz="0.0 0.035 0.02"/>
            <geometry>
                    <box size="0.04 0.07 0.04"/>
            </geometry>
        </collision>
        <xacro:inertial_box mass="1" x="0.04" y="0.07" z="0.04">
              <origin xyz="0.0 0.035 0.02" rpy="0.0 0.0 0.0"/>
        </xacro:inertial_box>
    </link>


    <!-- JOINT BETWEEN LINK 6 AND LINK 7 ***NOTE THAT LINK 4 IS THE HEAD -->

    <joint name="link_6_7_joint" type="revolute">
        <parent link="link_6"/>
        <child link="link_7"/>
        <limit lower="-0.7854" upper="0.7854" velocity="50.0" effort="1000.0"/>
        <origin xyz="0.0 0.095 0.0" />
        <axis xyz="0 0 1"/>
        <joint_properties damping="6.0" friction="6.0"/>
      </joint>
    
    <!--  LINK 7-->

    <link name="link_7">
        <visual>
            <geometry>
                    <box size="0.04 0.07 0.04"/>
            </geometry>
            <origin xyz="0.0 0.035 0.02" rpy="0.0 0.0 0.0"/>
          <material name="black"/>
        </visual>
        <collision>
            <origin xyz="0.0 0.035 0.02"/>
            <geometry>
                    <box size="0.04 0.07 0.04"/>
            </geometry>
        </collision>
        <xacro:inertial_box mass="1" x="0.04" y="0.07" z="0.04">
              <origin xyz="0.0 0.035 0.02" rpy="0.0 0.0 0.0"/>
        </xacro:inertial_box>
    </link>


    <!-- JOINT BETWEEN LINK 7 AND LINK 8 ***NOTE THAT LINK 4 IS THE HEAD -->

    <joint name="link_7_8_joint" type="revolute">
        <parent link="link_7"/>
        <child link="link_8"/>
        <limit lower="-0.7854" upper="0.7854" velocity="50.0" effort="1000.0"/>
        <origin xyz="0.0 0.095 0.0" />
        <axis xyz="0 0 1"/>
        <joint_properties damping="6.0" friction="6.0"/>
      </joint>
    
    <!--  LINK 8-->

    <link name="link_8">
        <visual>
            <geometry>
                    <box size="0.04 0.07 0.04"/>
            </geometry>
            <origin xyz="0.0 0.035 0.02" rpy="0.0 0.0 0.0"/>
          <material name="orange"/>
        </visual>
        <collision>
            <origin xyz="0.0 0.035 0.02"/>
            <geometry>
                    <box size="0.04 0.07 0.04"/>
            </geometry>
        </collision>
        <xacro:inertial_box mass="1" x="0.04" y="0.07" z="0.04">
              <origin xyz="0.0 0.035 0.02" rpy="0.0 0.0 0.0"/>
        </xacro:inertial_box>
    </link>

    <!-- JOINT BETWEEN LINK 8 AND LINK 9 ***NOTE THAT LINK 4 IS THE HEAD -->

    <joint name="link_8_9_joint" type="revolute">
        <parent link="link_8"/>
        <child link="link_9"/>
        <limit lower="-0.7854" upper="0.7854" velocity="50.0" effort="1000.0"/>
        <origin xyz="0.0 0.095 0.0" />
        <axis xyz="0 0 1"/>
        <joint_properties damping="6.0" friction="6.0"/>
      </joint>
    
    <!--  LINK 9-->

    <link name="link_9">
        <visual>
            <geometry>
                    <box size="0.04 0.07 0.04"/>
            </geometry>
            <origin xyz="0.0 0.035 0.02" rpy="0.0 0.0 0.0"/>
          <material name="black"/>
        </visual>
        <collision>
            <origin xyz="0.0 0.035 0.02"/>
            <geometry>
                    <box size="0.04 0.07 0.04"/>
            </geometry>
        </collision>
        <xacro:inertial_box mass="1" x="0.04" y="0.07" z="0.04">
              <origin xyz="0.0 0.035 0.02" rpy="0.0 0.0 0.0"/>
        </xacro:inertial_box>
    </link>
    
    <gazebo>
          <plugin name="gazebo_ros_joint_state_publisher"
                    filename="libgazebo_ros_joint_state_publisher.so">
                    <update_rate>50</update_rate>
                    <joint_name>link_head_1_joint</joint_name>
                    <joint_name>link_1_2_joint</joint_name>
                    <joint_name>link_2_3_joint</joint_name>
                    <joint_name>link_3_4_joint</joint_name>
                    <joint_name>link_4_5_joint</joint_name>
                    <joint_name>link_5_6_joint</joint_name>
                    <joint_name>link_6_7_joint</joint_name>
                    <joint_name>link_7_8_joint</joint_name>
                    <joint_name>link_8_9_joint</joint_name>
        </plugin>
</gazebo>
</robot>
